<tt>
Hi&nbsp;there,&nbsp;&lt;br&gt;<br>
&lt;br&gt;<br>
I&nbsp;am&nbsp;setting&nbsp;up&nbsp;a&nbsp;database&nbsp;that&nbsp;is&nbsp;built&nbsp;upon&nbsp;a&nbsp;mod_python.&nbsp;When&nbsp;I&nbsp;accessed&lt;br&gt;<br>
the&nbsp;database&nbsp;with&nbsp;a&nbsp;browser,&nbsp;it&nbsp;reported&nbsp;an&nbsp;error:&lt;br&gt;<br>
&lt;br&gt;<br>
===========================================[&nbsp;start&nbsp;]&lt;br&gt;<br>
Mod_python&nbsp;error:&nbsp;&amp;quot;PythonAuthenHandler&nbsp;access&amp;quot;&lt;br&gt;<br>
&lt;br&gt;<br>
Traceback&nbsp;(most&nbsp;recent&nbsp;call&nbsp;last):&lt;br&gt;<br>
&lt;br&gt;<br>
&amp;nbsp;&nbsp;File&nbsp;&amp;quot;/usr/lib/python2.3/site-packages/mod_python/apache.py&amp;quot;,&nbsp;line&nbsp;299,&nbsp;in&nbsp;HandlerDispatch&lt;br&gt;<br>
&amp;nbsp;&amp;nbsp;&amp;nbsp;&nbsp;result&nbsp;=&nbsp;object(req)&lt;br&gt;<br>
&lt;br&gt;<br>
&amp;nbsp;&nbsp;File&nbsp;&amp;quot;/home/emen2/public_html/emen2/access.py&amp;quot;,&nbsp;line&nbsp;20,&nbsp;in&nbsp;authenhandler&lt;br&gt;<br>
&amp;nbsp;&amp;nbsp;&amp;nbsp;&nbsp;ctxid=db.login(req.user,req.get_basic_auth_pw())&lt;br&gt;<br>
&lt;br&gt;<br>
&amp;nbsp;&nbsp;File&nbsp;&amp;quot;/home/emen2/DBProxy.py&amp;quot;,&nbsp;line&nbsp;28,&nbsp;in&nbsp;&lt;br&gt;<br>
&amp;nbsp;&amp;nbsp;&amp;nbsp;&nbsp;return&nbsp;lambda&nbsp;*x:&nbsp;self(name,*x)&lt;br&gt;<br>
&lt;br&gt;<br>
&amp;nbsp;&nbsp;File&nbsp;&amp;quot;/home/emen2/DBProxy.py&amp;quot;,&nbsp;line&nbsp;33,&nbsp;in&nbsp;__call__&lt;br&gt;<br>
&amp;nbsp;&amp;nbsp;&amp;nbsp;&nbsp;return&nbsp;load(self.iso[1])&lt;br&gt;<br>
&lt;br&gt;<br>
EOFError&lt;br&gt;<br>
=============================================[&nbsp;end&nbsp;]&lt;br&gt;<br>
&lt;br&gt;<br>
I&nbsp;believed&nbsp;it's&nbsp;due&nbsp;to&nbsp;an&nbsp;imcomplete&nbsp;installation&nbsp;of&nbsp;mod_python&nbsp;so&nbsp;I&nbsp;went&nbsp;ahead&lt;br&gt;<br>
to&nbsp;run&nbsp;the&nbsp;test.py&nbsp;came&nbsp;with&nbsp;mod_python.&nbsp;It&nbsp;reported&nbsp;many&nbsp;errors,&nbsp;mostly&nbsp;due&nbsp;to&lt;br&gt;<br>
a&nbsp;socket.error&nbsp;like:&lt;br&gt;<br>
&lt;br&gt;<br>
=============================================[&nbsp;start&nbsp;]&lt;br&gt;<br>
ERROR:&nbsp;test_req_document_root&nbsp;(__main__.PerRequestTestCase)&lt;br&gt;<br>
----------------------------------------------------------------------&lt;br&gt;<br>
Traceback&nbsp;(most&nbsp;recent&nbsp;call&nbsp;last):&lt;br&gt;<br>
&amp;nbsp;&nbsp;File&nbsp;&amp;quot;test.py&amp;quot;,&nbsp;line&nbsp;306,&nbsp;in&nbsp;test_req_document_root&lt;br&gt;<br>
&amp;nbsp;&amp;nbsp;&amp;nbsp;&nbsp;rsp&nbsp;=&nbsp;self.vhost_get(&amp;quot;test_req_document_root&amp;quot;)&lt;br&gt;<br>
&amp;nbsp;&nbsp;File&nbsp;&amp;quot;test.py&amp;quot;,&nbsp;line&nbsp;282,&nbsp;in&nbsp;vhost_get&lt;br&gt;<br>
&amp;nbsp;&amp;nbsp;&amp;nbsp;&nbsp;conn.endheaders()&lt;br&gt;<br>
&amp;nbsp;&nbsp;File&nbsp;&amp;quot;/usr/lib/python2.3/httplib.py&amp;quot;,&nbsp;line&nbsp;712,&nbsp;in&nbsp;endheaders&lt;br&gt;<br>
&amp;nbsp;&amp;nbsp;&amp;nbsp;&nbsp;self._send_output()&lt;br&gt;<br>
&amp;nbsp;&nbsp;File&nbsp;&amp;quot;/usr/lib/python2.3/httplib.py&amp;quot;,&nbsp;line&nbsp;597,&nbsp;in&nbsp;_send_output&lt;br&gt;<br>
&amp;nbsp;&amp;nbsp;&amp;nbsp;&nbsp;self.send(msg)&lt;br&gt;<br>
&amp;nbsp;&nbsp;File&nbsp;&amp;quot;/usr/lib/python2.3/httplib.py&amp;quot;,&nbsp;line&nbsp;564,&nbsp;in&nbsp;send&lt;br&gt;<br>
&amp;nbsp;&amp;nbsp;&amp;nbsp;&nbsp;self.connect()&lt;br&gt;<br>
&amp;nbsp;&nbsp;File&nbsp;&amp;quot;/usr/lib/python2.3/httplib.py&amp;quot;,&nbsp;line&nbsp;548,&nbsp;in&nbsp;connect&lt;br&gt;<br>
&amp;nbsp;&amp;nbsp;&amp;nbsp;&nbsp;raise&nbsp;socket.error,&nbsp;msg&lt;br&gt;<br>
error:&nbsp;(111,&nbsp;'Connection&nbsp;refused')&lt;br&gt;<br>
=============================================&nbsp;[&nbsp;end&nbsp;]&lt;br&gt;<br>
&lt;br&gt;<br>
How&nbsp;can&nbsp;I&nbsp;solve&nbsp;this&nbsp;problem?&nbsp;&lt;br&gt;<br>
Thx&nbsp;in&nbsp;advance;.&lt;br&gt;<br>
&lt;br&gt;<br>
pan&lt;br&gt;<br>
&lt;br&gt;<br>
&lt;br&gt;<br>

</tt>
