<!DOCTYPE HTML PUBLIC "-//W3C//DTD HTML 3.2//EN">
<HTML>
 <HEAD>
   <TITLE> [mod_python] test doesn't work
   </TITLE>
   <LINK REL="Index" HREF="index.html" >
   <LINK REL="made" HREF="mailto:mod_python%40modpython.org?Subject=%5Bmod_python%5D%20test%20doesn%27t%20work&In-Reply-To=003d01bfdb0b%2452f1e150%241d0eaad1%40edalearning.com">
   <META NAME="robots" CONTENT="index,nofollow">
   <META http-equiv="Content-Type" content="text/html; charset=us-ascii">
   <LINK REL="Previous"  HREF="003830.html">
   <LINK REL="Next"  HREF="003832.html">
 </HEAD>
 <BODY BGCOLOR="#ffffff">
   <H1>[mod_python] test doesn't work</H1>
    <B>Gregory Trubetskoy</B> 
    <A HREF="mailto:mod_python%40modpython.org?Subject=%5Bmod_python%5D%20test%20doesn%27t%20work&In-Reply-To=003d01bfdb0b%2452f1e150%241d0eaad1%40edalearning.com"
       TITLE="[mod_python] test doesn't work">grisha at modpython.org
       </A><BR>
    <I>Tue Jun 20 21:41:20 EST 2000</I>
    <P><UL>
        <LI>Previous message: <A HREF="003830.html">[mod_python] test doesn't work
</A></li>
        <LI>Next message: <A HREF="003832.html">[mod_python] test doesn't work
</A></li>
         <LI> <B>Messages sorted by:</B> 
              <a href="date.html#3831">[ date ]</a>
              <a href="thread.html#3831">[ thread ]</a>
              <a href="subject.html#3831">[ subject ]</a>
              <a href="author.html#3831">[ author ]</a>
         </LI>
       </UL>
    <HR>  
<table border=0 width="100%"><tr><td>
<!--beginarticle-->
<PRE>There is a module _apache which is only available from within
mod_python. However, if you comment out the 

from mod_python import apache

line, you should be able to import it from the command line.

I'm a little puzzled by this error, since everyone who has experienced it
never gave any logical reason as to what they did to fix this. It seems to
go away magically after they mes around for a while.

I am almost certain that this is caused by

1. a syntax error in test.py
2. a permissions problem

Grisha

On Tue, 20 Jun 2000, Howard Williams wrote:

&gt;<i> Hi
</I>&gt;<i> 
</I>&gt;<i> I've just installed the mod_python using all the latest source code for
</I>&gt;<i> apache, python, and from the modpython.org site.
</I>&gt;<i> 
</I>&gt;<i> I can't seem to run the tester:  So I've seen some postings from last month
</I>&gt;<i> about this with a similar &quot;AttributeError: handler&quot; title, but they didn't
</I>&gt;<i> seem to apply.
</I>&gt;<i> 
</I>&gt;<i> When I run &quot;python test.py&quot; (which I'm not convinced is supposed to be
</I>&gt;<i> possible) from a command line, I get the following output to stderr:
</I>&gt;<i> ***********************************************************
</I>&gt;<i> Traceback (innermost last):
</I>&gt;<i>   File &quot;test.py&quot;, line 1, in ?
</I>&gt;<i>     from mod_python import apache
</I>&gt;<i>   File &quot;/usr/local/lib/python1.5/site-packages/mod_python/apache.py&quot;, line
</I>&gt;<i> 18, in ?
</I>&gt;<i>     import _apache
</I>&gt;<i> ImportError: No module named _apache
</I>&gt;<i> 
</I>&gt;<i> ***********************************************************
</I>&gt;<i> 
</I>&gt;<i> 
</I>&gt;<i> My directories are laid out as follows:
</I>&gt;<i> 
</I>&gt;<i> /usr/local/lib/python1.5/site-packages/mod_python/apache.py
</I>&gt;<i> /usr/local/lib/python1.5/site-packages/mod_python/apache.pyc
</I>&gt;<i> /usr/local/lib/python1.5/site-packages/mod_python/cgihandler.py
</I>&gt;<i> /usr/local/lib/python1.5/site-packages/mod_python/cgihandler.pyc
</I>&gt;<i> /usr/local/lib/python1.5/site-packages/mod_python/httpdapi.py
</I>&gt;<i> /usr/local/lib/python1.5/site-packages/mod_python/httpdapi.pyc
</I>&gt;<i> /usr/local/lib/python1.5/site-packages/mod_python/zhandler.py
</I>&gt;<i> /usr/local/lib/python1.5/site-packages/mod_python/zhandler.pyc
</I>&gt;<i> 
</I>&gt;<i> 
</I>&gt;<i> I get this error:
</I>&gt;<i> *********************************
</I>&gt;<i> ERROR mod_python: &quot;PythonHandler test&quot;
</I>&gt;<i> 
</I>&gt;<i> Traceback (innermost last):
</I>&gt;<i> 
</I>&gt;<i>   File &quot;/usr/local/lib/python1.5/site-packages/mod_python/apache.py&quot;, line
</I>&gt;<i> 96, in Dispatch
</I>&gt;<i>     object = self.resolve_object(module, object_str)
</I>&gt;<i> 
</I>&gt;<i>   File &quot;/usr/local/lib/python1.5/site-packages/mod_python/apache.py&quot;, line
</I>&gt;<i> 42, in resolve_object
</I>&gt;<i>     obj = getattr(obj, obj_str)
</I>&gt;<i> 
</I>&gt;<i> AttributeError: handler
</I>&gt;<i> ************************************************
</I>&gt;<i> 
</I>&gt;<i> 
</I>&gt;<i> Here's the apache error_log:
</I>&gt;<i> ************************************************
</I>&gt;<i> [Tue Jun 20 15:47:37 2000] [notice] Apache/1.3.12 (Unix) configured --
</I>&gt;<i> resuming normal operations
</I>&gt;<i> [Tue Jun 20 15:47:46 2000] [error] PythonHandler test: Traceback (innermost
</I>&gt;<i> last):
</I>&gt;<i> [Tue Jun 20 15:47:46 2000] [error] PythonHandler test:   File
</I>&gt;<i> &quot;/usr/local/lib/python1.5/site-packages/mod_python/apache.py&quot;, line 96, in
</I>&gt;<i> Dispatch
</I>&gt;<i>     object = self.resolve_object(module, object_str)
</I>&gt;<i> [Tue Jun 20 15:47:46 2000] [error] PythonHandler test:   File
</I>&gt;<i> &quot;/usr/local/lib/python1.5/site-packages/mod_python/apache.py&quot;, line 42, in
</I>&gt;<i> resolve_object
</I>&gt;<i>     obj = getattr(obj, obj_str)
</I>&gt;<i> [Tue Jun 20 15:47:46 2000] [error] PythonHandler test: AttributeError:
</I>&gt;<i> handler
</I>&gt;<i> ************************************************
</I>&gt;<i> 
</I>&gt;<i> 
</I>&gt;<i> 
</I>&gt;<i>  Thanks for any help you can provide !!!!   :)
</I>&gt;<i> 
</I>&gt;<i> 
</I>&gt;<i> HOWARD WILLIAMS
</I>&gt;<i> marchFIRST
</I>&gt;<i> 23422 Mill Creek Drive., Suite 100
</I>&gt;<i> Laguna Hills, CA 92653
</I>&gt;<i> ph: (949) 461-5480
</I>&gt;<i> fax: (949) 461-5669
</I>&gt;<i> <A HREF="http://mailman.modpython.org/mailman/listinfo/mod_python">howard.williams at marchFIRST.com</A>
</I>&gt;<i> www.marchFIRST.com
</I>&gt;<i> 
</I>&gt;<i> 
</I>

</PRE>
<!--endarticle-->
</td>
<td align="right" valign="top">
<script>
  (function(i,s,o,g,r,a,m){i['GoogleAnalyticsObject']=r;i[r]=i[r]||function(){
  (i[r].q=i[r].q||[]).push(arguments)},i[r].l=1*new Date();a=s.createElement(o),
  m=s.getElementsByTagName(o)[0];a.async=1;a.src=g;m.parentNode.insertBefore(a,m)
  })(window,document,'script','//www.google-analytics.com/analytics.js','ga');
  ga('create', 'UA-42971867-2', 'modpython.org');
  ga('send', 'pageview');
</script>

</td>
</table>
    <HR>
    <P><UL>
        <!--threads-->
	<LI>Previous message: <A HREF="003830.html">[mod_python] test doesn't work
</A></li>
	<LI>Next message: <A HREF="003832.html">[mod_python] test doesn't work
</A></li>
         <LI> <B>Messages sorted by:</B> 
              <a href="date.html#3831">[ date ]</a>
              <a href="thread.html#3831">[ thread ]</a>
              <a href="subject.html#3831">[ subject ]</a>
              <a href="author.html#3831">[ author ]</a>
         </LI>
       </UL>

<hr>
<a href="http://mailman.modpython.org/mailman/listinfo/mod_python">More information about the Mod_python
mailing list</a><br>
</body></html>
