<!DOCTYPE HTML PUBLIC "-//W3C//DTD HTML 3.2//EN">
<HTML>
 <HEAD>
   <TITLE> [mod_python] Bug when using Publisher with Callable Objects:
   </TITLE>
   <LINK REL="Index" HREF="index.html" >
   <LINK REL="made" HREF="mailto:mod_python%40modpython.org?Subject=%5Bmod_python%5D%20Bug%20when%20using%20Publisher%20with%20Callable%20Objects%3A&In-Reply-To=">
   <META NAME="robots" CONTENT="index,nofollow">
   <META http-equiv="Content-Type" content="text/html; charset=us-ascii">
   <LINK REL="Previous"  HREF="016693.html">
   <LINK REL="Next"  HREF="016701.html">
 </HEAD>
 <BODY BGCOLOR="#ffffff">
   <H1>[mod_python] Bug when using Publisher with Callable Objects:</H1>
<table border=0 width="100%"><tr><td valign="top">
    <B>Jon-Pierre Gentil</B> 
    <A HREF="mailto:mod_python%40modpython.org?Subject=%5Bmod_python%5D%20Bug%20when%20using%20Publisher%20with%20Callable%20Objects%3A&In-Reply-To="
       TITLE="[mod_python] Bug when using Publisher with Callable Objects:">jgentil at sebistar.net
       </A><BR>
    <I>Wed Oct 27 14:02:51 EDT 2004</I>
    <P><UL>
        <LI>Previous message: <A HREF="016693.html">[mod_python] newbie question
</A></li>
        <LI>Next message: <A HREF="016701.html">[mod_python] Sessions Question
</A></li>
         <LI> <B>Messages sorted by:</B> 
              <a href="date.html#16694">[ date ]</a>
              <a href="thread.html#16694">[ thread ]</a>
              <a href="subject.html#16694">[ subject ]</a>
              <a href="author.html#16694">[ author ]</a>
         </LI>
       </UL>
    <HR>  
<!--beginarticle-->
<PRE>-----BEGIN PGP SIGNED MESSAGE-----
Hash: RIPEMD160

I get the following error when trying to use an instance of a callable
object instead of a function for the &quot;functions&quot; in Publisher.

Mod_python error: &quot;PythonHandler mod_python.publisher&quot;

Traceback (most recent call last):

  File &quot;/usr/lib/python2.3/site-packages/mod_python/apache.py&quot;, line
299, in HandlerDispatch
    result = object(req)

  File &quot;/usr/lib/python2.3/site-packages/mod_python/publisher.py&quot;,
line 136, in handler
    result = util.apply_fs_data(object, req.form, req=req)

  File &quot;/usr/lib/python2.3/site-packages/mod_python/util.py&quot;, line
356, in apply_fs_data
    if not (fc.co_flags &amp; 0x08):

UnboundLocalError: local variable 'fc' referenced before assignment

It appears taht apply_fs_data never expects for the object that is
passed to be a callable object instead of a function.

Any ideas on what to do?

Thanks!!!
-----BEGIN PGP SIGNATURE-----
Version: GnuPG v1.2.5 (GNU/Linux)

iEYEAREDAAYFAkF/4ssACgkQOrVFmaIbww6HhQCgkP1m7Nx0GK0e7IHezuuVV1Ah
sygAniQ5j89jnW7JkzvCikqovuGDDrZM
=a+ph
-----END PGP SIGNATURE-----
</PRE>









<!--endarticle-->
    <HR>
    <P><UL>
        <!--threads-->
	<LI>Previous message: <A HREF="016693.html">[mod_python] newbie question
</A></li>
	<LI>Next message: <A HREF="016701.html">[mod_python] Sessions Question
</A></li>
         <LI> <B>Messages sorted by:</B> 
              <a href="date.html#16694">[ date ]</a>
              <a href="thread.html#16694">[ thread ]</a>
              <a href="subject.html#16694">[ subject ]</a>
              <a href="author.html#16694">[ author ]</a>
         </LI>
       </UL>

</td>
<td align="right" valign="top">
<script type="text/javascript"><!--
google_ad_client = "pub-9718360309690383";
google_ad_width = 120;
google_ad_height = 600;
google_ad_format = "120x600_as";
google_color_border = "CCCCCC";
google_color_bg = "FFFFFF";
google_color_link = "000000";
google_color_url = "666666";
google_color_text = "333333";
//--></script>
<script type="text/javascript"
  src="DISABLEhttp://pagead2.googlesyndication.com/pagead/show_ads.js">
</script>
</td>
</table>

<hr>
<a href="http://mailman.modpython.org/mailman/listinfo/mod_python">More information about the Mod_python
mailing list</a><br>
</body></html>
