<!DOCTYPE HTML PUBLIC "-//W3C//DTD HTML 3.2//EN">
<HTML>
 <HEAD>
   <TITLE> [mod_python] internal error again!
   </TITLE>
   <LINK REL="Index" HREF="index.html" >
   <LINK REL="made" HREF="mailto:mod_python%40modpython.org?Subject=%5Bmod_python%5D%20internal%20error%20again%21&In-Reply-To=">
   <META NAME="robots" CONTENT="index,nofollow">
   <META http-equiv="Content-Type" content="text/html; charset=us-ascii">
   <LINK REL="Previous"  HREF="020813.html">
   <LINK REL="Next"  HREF="020817.html">
 </HEAD>
 <BODY BGCOLOR="#ffffff">
   <H1>[mod_python] internal error again!</H1>
<table border=0 width="100%"><tr><td valign="top">
    <B>nemesis128 at atarax.org</B> 
    <A HREF="mailto:mod_python%40modpython.org?Subject=%5Bmod_python%5D%20internal%20error%20again%21&In-Reply-To="
       TITLE="[mod_python] internal error again!">nemesis128 at atarax.org
       </A><BR>
    <I>Sat Apr  8 07:28:42 EDT 2006</I>
    <P><UL>
        <LI>Previous message: <A HREF="020813.html">[mod_python] Mod Python problems
</A></li>
        <LI>Next message: <A HREF="020817.html">[mod_python] internal error again!
</A></li>
         <LI> <B>Messages sorted by:</B> 
              <a href="date.html#20814">[ date ]</a>
              <a href="thread.html#20814">[ thread ]</a>
              <a href="subject.html#20814">[ subject ]</a>
              <a href="author.html#20814">[ author ]</a>
         </LI>
       </UL>
    <HR>  
<!--beginarticle-->
<PRE>Hello,

First i'd like to thank alll the people behind mod_python! =)

All worked fine for me with apache 1.3.
Now i have installed apache 2 and i have that usual problem of Internal Server
Error 500.

I've read all the faqs about it, nothing works.

Detailed:

 - Mandriva Linux 2006
 - Compiled python 2.4.3
 - Compiled apache 2.0.55
 - mod python 3.2.8 (i even tried to compile it with the latest flex 2.5.33)
 - i tried htaccess &amp; httpd.conf directives
 - with all examples given in the doc.
 - i always get the same error log:

-------------------------------------------------------------------
[Fri Apr 07 23:19:20 2006] [notice] mod_python: Creating 32 session mutexes
based on 150 max processes and 0 max threads.
[Fri Apr 07 23:19:20 2006] [notice] Apache/2.0.55 (Unix) mod_python/3.2.8
Python/2.4.3 configured -
- resuming normal operations
[Fri Apr 07 23:19:23 2006] [error] make_obcallback: could not import
mod_python.apache.\n
'import site' failed; use -v for traceback
'import site' failed; use -v for traceback
ImportError: No module named mod_python.apache
[Fri Apr 07 23:19:23 2006] [error] python_handler: no interpreter callback
found.
[Fri Apr 07 23:19:23 2006] [error] [client ::1] python_handler: Can't get/create
interpreter., refe
rer: <A HREF="http://localhost/%7Esm/">http://localhost/%7Esm/</A>
----------------------------------------------------------------------

Well, sys.path is OK too, but cannot import site (nor mod_python) !!


I also get that kind of error on apache startup sometimes, and i just don't know
if it has something to do with the problem explained above:

----------------------------------------------------------------------
[Sat Apr 08 02:13:37 2006] [notice] mod_python: Creating 32 session mutexes
based on 150 max proces
ses and 0 max threads.
[Sat Apr 08 02:13:37 2006] [error] (28)No space left on device: mod_python:
Failed to create global
 mutex 21 of 32 (/tmp/mpmtx1145121).
[Sat Apr 08 02:13:37 2006] [error] mod_python: We can probably continue, but
with diminished abilit
y to process session locks.
[Sat Apr 08 02:13:37 2006] [error] mod_python: Hint: On Linux, the problem may
be the number of ava
ilable semaphores, check 'sysctl kernel.sem'
[Sat Apr 08 02:13:37 2006] [notice] Apache/2.0.55 (Unix) mod_python/3.2.8
Python/2.4.3 configured -
- resuming normal operations
-------------------------------------------------------------------------

Any help ?

Thanx alot++++

   Stan.


</PRE>




<!--endarticle-->
    <HR>
    <P><UL>
        <!--threads-->
	<LI>Previous message: <A HREF="020813.html">[mod_python] Mod Python problems
</A></li>
	<LI>Next message: <A HREF="020817.html">[mod_python] internal error again!
</A></li>
         <LI> <B>Messages sorted by:</B> 
              <a href="date.html#20814">[ date ]</a>
              <a href="thread.html#20814">[ thread ]</a>
              <a href="subject.html#20814">[ subject ]</a>
              <a href="author.html#20814">[ author ]</a>
         </LI>
       </UL>

</td>
<td align="right" valign="top">
<script>
  (function(i,s,o,g,r,a,m){i['GoogleAnalyticsObject']=r;i[r]=i[r]||function(){
  (i[r].q=i[r].q||[]).push(arguments)},i[r].l=1*new Date();a=s.createElement(o),
  m=s.getElementsByTagName(o)[0];a.async=1;a.src=g;m.parentNode.insertBefore(a,m)
  })(window,document,'script','//www.google-analytics.com/analytics.js','ga');
  ga('create', 'UA-42971867-2', 'modpython.org');
  ga('send', 'pageview');
</script>

</td>
</table>

<hr>
<a href="http://mailman.modpython.org/mailman/listinfo/mod_python">More information about the Mod_python
mailing list</a><br>
</body></html>
